Workbook

Sheet Cover
B2: =F5 & " Financial Model" -> Apple Inc. Financial Model
B3: Scenario Analysis | E3: Genaral Settings | H3: Table of Contents
B5: Live Scenario | C5: Base Case | E5: Company Name | F5: Apple Inc. | H5: Cover Page
E6: Ticker | F6: AAPL | H6: Assumptions & Drivers
B7: Alerts | E7: Sector | F7: Technology | H7: Revenue Build
E8: Fiscal Year End Date | F8: September | H8: Income Statement
B9: Balance Sheet Balances? | C9: =IF(Checks!D10=0,"✓ Balanced","✗ ERROR") -> ✓ Balanced | E9: Historical period | F9: FYE2022 - FYE2024 | H9: Balance Sheet
E10: Projection Period | F10: FYE2025 - FYE2033 | H10: Cash Flow Statement
E11: Reference Price | F11: 299.24 | H11: Schedules
E12: Market Cap | F12: =F11*F13 -> 4421.6759 | H12: DCF Valuation
E13: Shares Outstanding | F13: 14.776353 | H13: Trading Comps
H14: Precedent Transactions
H15: Sensitivity Analysis
H16: Checks
B19: Prepared by: | C19: Jessica ZIREGBE
B20: Date: | C20: June 2026
B21: Version: | C21: v1.0

Sheet Assumptions
B2: Assumptions
D3: 2022 | E3: =D3+1 -> 2023 | F3: =E3+1 -> 2024 | G3: =F3+1 -> 2025 | H3: =G3+1 -> 2026 | I3: =H3+1 -> 2027 | J3: =I3+1 -> 2028 | K3: =J3+1 -> 2029 | L3: =K3+1 -> 2030 | ... O3: =N3+1 -> 2033
B4: Revenue Drivers
B6: Products growth % | G6: 0.04 | H6: =('Revenue Build'!H3+'Revenue Build'!H4+'Revenue Build'!H5)/('Revenue Build'!G3+'Revenue Build'!G4+'Revenue Build'!G5+'Revenue Build'!G6)-1 -> -0.076192936 | I6: =('Revenue Build'!I3+'Revenue Build'!I4+'Revenue Build'!I5)/('Revenue Build'!H3+'Revenue Build'!H4+'Revenue Build'!H5+'Revenue Build'!H6)-1 -> -0.088231628 | J6: =('Revenue Build'!J3+'Revenue Build'!J4+'Revenue Build'!J5)/('Revenue Build'!I3+'Revenue Build'!I4+'Revenue Build'!I5+'Revenue Build'!I6)-1 -> -0.088993946 | K6: =('Revenue Build'!K3+'Revenue Build'!K4+'Revenue Build'!K5)/('Revenue Build'!J3+'Revenue Build'!J4+'Revenue Build'!J5+'Revenue Build'!J6)-1 -> -0.093804413 | L6: =('Revenue Build'!L3+'Revenue Build'!L4+'Revenue Build'!L5)/('Revenue Build'!K3+'Revenue Build'!K4+'Revenue Build'!K5+'Revenue Build'!K6)-1 -> -0.095258766 | M6: =('Revenue Build'!M3+'Revenue Build'!M4+'Revenue Build'!M5)/('Revenue Build'!L3+'Revenue Build'!L4+'Revenue Build'!L5+'Revenue Build'!L6)-1 -> -0.10004611 | N6: =('Revenue Build'!N3+'Revenue Build'!N4+'Revenue Build'!N5)/('Revenue Build'!M3+'Revenue Build'!M4+'Revenue Build'!M5+'Revenue Build'!M6)-1 -> -0.10202293 | O6: =('Revenue Build'!O3+'Revenue Build'!O4+'Revenue Build'!O5)/('Revenue Build'!N3+'Revenue Build'!N4+'Revenue Build'!N5+'Revenue Build'!N6)-1 -> -0.10349483
B7: Service growth% | G7: 0.135 | H7: ='Revenue Build'!H7/'Revenue Build'!G7-1 -> 0.14 | I7: 0.09 | J7: 0.08 | K7: 0.06 | L7: 0.05 | M7: 0.05 | N7: 0.045 | O7: 0.04
B9: Cost Structure
B10: COGS as a % Revenue | D10: ='Income Statement'!D10/'Income Statement'!D8 -> 0.56690369 | E10: ='Income Statement'!E10/'Income Statement'!E8 -> 0.5586887 | F10: ='Income Statement'!F10/'Income Statement'!F8 -> 0.5379365 | G10: 0.531 | H10: 0.531 | I10: 0.525 | J10: 0.519 | K10: 0.514 | L10: 0.507 | M10: 0.501 | N10: 0.495 | O10: 0.489
B12: R&D as % of Revenue | D12: 0.067 | E12: 0.078 | F12: 0.08 | G12: 0.08 | H12: 0.081 | I12: 0.082 | J12: 0.083 | K12: 0.084 | L12: 0.085 | M12: 0.086 | N12: 0.087 | O12: 0.088
B13: SG&A as % of Revenue | D13: 0.064 | E13: 0.065 | F13: 0.067 | G13: 0.066 | H13: 0.065 | I13: ='Income Statement'!I15/'Income Statement'!I8 -> 0.065 | J13: ='Income Statement'!J15/'Income Statement'!J8 -> 0.065 | K13: ='Income Statement'!K15/'Income Statement'!K8 -> 0.065 | L13: ='Income Statement'!L15/'Income Statement'!L8 -> 0.065 | M13: ='Income Statement'!M15/'Income Statement'!M8 -> 0.065 | N13: ='Income Statement'!N15/'Income Statement'!N8 -> 0.065 | O13: ='Income Statement'!O15/'Income Statement'!O8 -> 0.065
B15: Other & Taxes
B16: Other income as % of revenue | D16: -0.0008 | E16: -0.0015 | F16: 0.0007 | G16: -0.0008 | H16: -0.0008 | I16: -0.0008 | J16: -0.0008 | K16: -0.0008 | L16: -0.0008 | M16: -0.0008 | N16: -0.0008 | O16: -0.0008
B18: Effective tax rate (%) | D18: 0.162 | E18: 0.147 | F18: 0.241 | G18: 0.156 | H18: 0.16 | I18: 0.16 | J18: 0.16 | K18: 0.16 | L18: 0.16 | M18: 0.16 | N18: 0.16 | O18: 0.16
B20: Cash Flow Drivers
B21: Capex / Sales | D21: 0.027 | E21: 0.029 | F21: 0.024 | G21: 0.031 | H21: 0.031 | I21: 0.031 | J21: 0.031 | K21: 0.031 | L21: 0.031 | M21: 0.031 | N21: 0.031 | O21: 0.031
B22: Depreciation (% of revenue) | H22: 0.028 | I22: 0.028 | J22: 0.028 | K22: 0.028 | L22: 0.028 | M22: 0.028 | N22: 0.028 | O22: 0.028
B23: PP&E Depreciation (% of revenue) | D23: 0.0221 | E23: 0.0222 | F23: 0.021 | G23: 0.0192 | H23: 0.019 | I23: 0.019 | J23: 0.019 | K23: 0.019 | L23: 0.019 | M23: 0.019 | N23: 0.019 | O23: 0.019 | P23: Source: Apple 10-K FY2025 Note 5, p.39 |IS, p.29
B24: DSO (days) | D24: 27 | E24: 28 | F24: 31 | G24: 35 | H24: 35 | I24: 35 | J24: 35 | K24: 35 | L24: 35 | M24: 35 | N24: 35 | O24: 35
B25: DIO (days) | D25: 9 | E25: 8 | F25: 13 | G25: 9 | H25: 9 | I25: 9 | J25: 9 | K25: 9 | L25: 9 | M25: 9 | N25: 9 | O25: 9
B26: DPO (days) | D26: 107 | E26: 109 | F26: 120 | G26: 115 | H26: 115 | I26: 115 | J26: 115 | K26: 115 | L26: 115 | M26: 115 | N26: 115 | O26: 115
B28: Share Assumption
B29: Share count change (%) | H29: 0.03 | I29: 0.03 | J29: 0.03 | K29: 0.03 | L29: 0.03 | M29: 0.03 | N29: 0.03 | O29: 0.03
B30: Dilution ( %) | H30: 0.007 | I30: 0.007 | J30: 0.007 | K30: 0.007 | L30: 0.007 | M30: 0.007 | N30: 0.007 | O30: 0.007
B32: Margins
B33: Gross margin trend | D33: ='Income Statement'!D11/'Income Statement'!D8 -> 0.43309631 | E33: ='Income Statement'!E11/'Income Statement'!E8 -> 0.4413113 | F33: ='Income Statement'!F11/'Income Statement'!F8 -> 0.4620635 | G33: ='Income Statement'!G11/'Income Statement'!G8 -> 0.46905164 | H33: ='Income Statement'!H11/'Income Statement'!H8 -> 0.469 | I33: ='Income Statement'!I11/'Income Statement'!I8 -> 0.475 | J33: ='Income Statement'!J11/'Income Statement'!J8 -> 0.481 | K33: ='Income Statement'!K11/'Income Statement'!K8 -> 0.486 | ... O33: ='Income Statement'!O11/'Income Statement'!O8 -> 0.511
B34: EBIT margin | D34: ='Income Statement'!D18/'Income Statement'!D8 -> 0.30288744 | E34: ='Income Statement'!E18/'Income Statement'!E8 -> 0.29821412 | F34: ='Income Statement'!F18/'Income Statement'!F8 -> 0.31510223 | G34: ='Income Statement'!G18/'Income Statement'!G8 -> 0.319708 | H34: ='Income Statement'!H18/'Income Statement'!H8 -> 0.323 | I34: ='Income Statement'!I18/'Income Statement'!I8 -> 0.329 | J34: ='Income Statement'!J18/'Income Statement'!J8 -> 0.334 | K34: ='Income Statement'!K18/'Income Statement'!K8 -> 0.338 | ... O34: ='Income Statement'!O18/'Income Statement'!O8 -> 0.359
B35: Net Margin | D35: ='Income Statement'!D22/'Income Statement'!D8 -> 0.25309641 | E35: ='Income Statement'!E22/'Income Statement'!E8 -> 0.25306234 | F35: ='Income Statement'!F22/'Income Statement'!F8 -> 0.23971256 | G35: ='Income Statement'!G22/'Income Statement'!G8 -> 0.26915064 | H35: ='Income Statement'!H22/'Income Statement'!H8 -> 0.270648 | I35: ='Income Statement'!I22/'Income Statement'!I8 -> 0.275688 | J35: ='Income Statement'!J22/'Income Statement'!J8 -> 0.279888 | K35: ='Income Statement'!K22/'Income Statement'!K8 -> 0.283248 | ... O35: ='Income Statement'!O22/'Income Statement'!O8 -> 0.300888
B37: Balance Drivers
B38: Marketable securities | D38: -0.02
B39: Vendor non-trade receivables | D39: 0.005
B40: Other current assets | D40: 0.02
B41: Other non-current assets | D41: 0.015
B42: Other current liabilities | D42: 0.02
B43: Deferred revenue | D43: 0.1
B44: Annual Dividend | G44: 15413 | H44: =G44*(1+H45) -> 16029.52 | I44: =H44*(1+I45) -> 16670.701 | J44: =I44*(1+J45) -> 17337.529 | K44: =J44*(1+K45) -> 18031.03 | L44: =K44*(1+L45) -> 18752.271 | M44: =L44*(1+M45) -> 19502.362 | N44: =M44*(1+N45) -> 20282.457 | O44: =N44*(1+O45) -> 21093.755 | P44: Source: Apple 10-K FY2025 p.33 CFS — Dividends paid $15,421M (using $15,413M declared per IS)
B45: Dividend growth rate | H45: 0.04 | I45: 0.04 | J45: 0.04 | K45: 0.04 | L45: 0.04 | M45: 0.04 | N45: 0.04 | O45: 0.04
B46: Annual Share Repurchases ($M) | D46: 89402 | E46: 77550 | F46: 94949 | G46: 90711 | H46: 89300 | I46: 85000 | J46: 80000 | K46: 75000 | L46: 70000 | M46: 65000 | N46: 60000 | O46: 55000
B47: Average repurchase price | D47: =-D46*1000/Schedules!D61 -> 157.23484 | E47: =-E46*1000/Schedules!E61 -> 164.50334 | F47: =-F46*1000/Schedules!F61 -> 190.13681 | G47: =-G46*1000/Schedules!G61 -> 225.83352 | H47: =G47*(1+0.1) -> 248.41687 | I47: =H47*(1+0.1) -> 273.25855 | J47: =I47*(1+0.1) -> 300.58441 | K47: =J47*(1+0.1) -> 330.64285 | L47: =K47*(1+0.1) -> 363.70714 | M47: =L47*(1+0.1) -> 400.07785 | N47: =M47*(1+0.1) -> 440.08563 | O47: =N47*(1+0.1) -> 484.0942 | P47: Avg Repurchase Price = Repurchase $M × 1,000 ÷ Shares Repurchased (000s)
B48: SBC (% of Revenue) | G48: 0.031 | H48: 0.031 | I48: 0.031 | J48: 0.031 | K48: 0.031 | L48: 0.031 | M48: 0.031 | N48: 0.031 | O48: 0.031
B49: RSU tax withholding (% of Revenue) | G49: 0.0143 | H49: 0.0143 | I49: 0.0143 | J49: 0.0143 | K49: 0.0143 | L49: 0.0143 | M49: 0.0143 | N49: 0.0143 | O49: 0.0143 | P49: Source: Apple 10-K FY2025 p.29 — SBC $12,863M / Revenue $416,161M = 3.1%
P50: Source: Apple 10-K FY2025 p.33 CFS — RSU taxes $5,960M / Revenue $416,161M = 1.43%
...

Sheet Revenue Build
B2: Net sales by category:
B3: iPhone | D3: 205489 | E3: 200583 | F3: 201183 | G3: 209586 | H3: =G3*(1+'Revenue Build'!H12) -> 219017.37 | I3: =H3*(1+'Revenue Build'!I12) -> 224492.8 | J3: =I3*(1+'Revenue Build'!J12) -> 230105.12 | K3: =J3*(1+'Revenue Build'!K12) -> 234707.23 | L3: =K3*(1+'Revenue Build'!L12) -> 239401.37 | M3: =L3*(1+'Revenue Build'!M12) -> 242992.39 | N3: =M3*(1+'Revenue Build'!N12) -> 246637.28 | O3: =N3*(1+'Revenue Build'!O12) -> 250336.84
B4: Mac | D4: 40177 | E4: 29357 | F4: 29984 | G4: 33708 | H4: =G4*(1+'Revenue Build'!H13) -> 35730.48 | I4: =H4*(1+'Revenue Build'!I13) -> 37517.004 | J4: =I4*(1+'Revenue Build'!J13) -> 39017.684 | K4: =J4*(1+'Revenue Build'!K13) -> 40383.303 | L4: =K4*(1+'Revenue Build'!L13) -> 41594.802 | M4: =L4*(1+'Revenue Build'!M13) -> 42842.646 | N4: =M4*(1+'Revenue Build'!N13) -> 43913.712 | O4: =N4*(1+'Revenue Build'!O13) -> 45011.555
B5: iPad | D5: 29292 | E5: 28300 | F5: 26694 | G5: 28023 | H5: =G5*(1+'Revenue Build'!H14) -> 28863.69 | I5: =H5*(1+'Revenue Build'!I14) -> 29440.964 | J5: =I5*(1+'Revenue Build'!J14) -> 29882.578 | K5: =J5*(1+'Revenue Build'!K14) -> 30181.404 | L5: =K5*(1+'Revenue Build'!L14) -> 30483.218 | M5: =L5*(1+'Revenue Build'!M14) -> 30635.634 | N5: =M5*(1+'Revenue Build'!N14) -> 30788.812 | O5: =N5*(1+'Revenue Build'!O14) -> 30942.756
B6: Wearables Home and Accessories | D6: 41241 | E6: 39845 | F6: 37005 | G6: 35686 | H6: =G6*(1+'Revenue Build'!H15) -> 36042.86 | I6: =H6*(1+'Revenue Build'!I15) -> 36763.717 | J6: =I6*(1+'Revenue Build'!J15) -> 37866.629 | K6: =J6*(1+'Revenue Build'!K15) -> 39002.628 | L6: =K6*(1+'Revenue Build'!L15) -> 40172.706 | M6: =L6*(1+'Revenue Build'!M15) -> 41377.888 | N6: =M6*(1+'Revenue Build'!N15) -> 42619.224 | O6: =N6*(1+'Revenue Build'!O15) -> 43897.801
B7: Services | D7: 78129 | E7: 85200 | F7: 96169 | G7: 109158 | H7: =G7*(1+'Revenue Build'!H16) -> 124440.12 | I7: =H7*(1+'Revenue Build'!I16) -> 140617.34 | J7: =I7*(1+'Revenue Build'!J16) -> 157491.42 | K7: =J7*(1+'Revenue Build'!K16) -> 174815.47 | L7: =K7*(1+'Revenue Build'!L16) -> 192297.02 | M7: =L7*(1+'Revenue Build'!M16) -> 209603.75 | N7: =M7*(1+'Revenue Build'!N16) -> 228468.09 | O7: =N7*(1+'Revenue Build'!O16) -> 246745.54
B8: Total net sales | D8: =SUM(D3:D7) -> 394328 | E8: =SUM(E3:E7) -> 383285 | F8: =SUM(F3:F7) -> 391035 | G8: =SUM(G3:G7) -> 416161 | H8: =SUM(H3:H7) -> 444094.52 | I8: =SUM(I3:I7) -> 468831.82 | J8: =SUM(J3:J7) -> 494363.43 | K8: =SUM(K3:K7) -> 519090.03 | ... O8: =SUM(O3:O7) -> 616934.48
B10: Assumptions:
B11: Revenue by segment growth:
B12: iPhone growth % | G12: =G3/F3-1 -> 0.041767943 | H12: 0.045 | I12: 0.025 | J12: 0.025 | K12: 0.02 | L12: 0.02 | M12: 0.015 | N12: 0.015 | O12: 0.015
B13: Mac growth % | G13: =G4/F4-1 -> 0.12419957 | H13: 0.06 | I13: 0.05 | J13: 0.04 | K13: 0.035 | L13: 0.03 | M13: 0.03 | N13: 0.025 | O13: 0.025
B14: iPad growth % | G14: =G5/F5-1 -> 0.049786469 | H14: 0.03 | I14: 0.02 | J14: 0.015 | K14: 0.01 | L14: 0.01 | M14: 0.005 | N14: 0.005 | O14: 0.005
B15: Wearables growth % | G15: =G6/F6-1 -> -0.035643832 | H15: 0.01 | I15: 0.02 | J15: 0.03 | K15: 0.03 | L15: 0.03 | M15: 0.03 | N15: 0.03 | O15: 0.03
B16: Services growth % | G16: =G7/F7-1 -> 0.13506431 | H16: 0.14 | I16: 0.13 | J16: 0.12 | K16: 0.11 | L16: 0.1 | M16: 0.09 | N16: 0.09 | O16: 0.08
B18: Revenue Build (FYE) | D18: 2022 | E18: =D18+1 -> 2023 | F18: =E18+1 -> 2024 | G18: =F18+1 -> 2025 | H18: =G18+1 -> 2026 | I18: =H18+1 -> 2027 | J18: =I18+1 -> 2028 | K18: =J18+1 -> 2029 | L18: =K18+1 -> 2030 | ... O18: =N18+1 -> 2033
B19: iPhone
B20: IPhone Revenue | D20: =D3 -> 205489 | E20: =E3 -> 200583 | F20: =F3 -> 201183 | G20: =G3 -> 209586 | H20: =H3 -> 219017.37 | I20: =I3 -> 224492.8 | J20: =J3 -> 230105.12 | K20: =K3 -> 234707.23 | ... O20: =O3 -> 250336.84
B21: % growth | H21: =H12 -> 0.045 | I21: =I12 -> 0.025 | J21: =J12 -> 0.025 | K21: =K12 -> 0.02 | L21: =L12 -> 0.02 | M21: =M12 -> 0.015 | N21: =N12 -> 0.015 | O21: =O12 -> 0.015
B23: Best Case | H23: =G20*(1+0.045) -> 219017.37 | I23: =H20*(1+0.035) -> 226682.98 | J23: =I20*(1+0.03) -> 231227.59 | K23: =J20*(1+0.03) -> 237008.28 | L23: =K20*(1+0.025) -> 240574.91 | M23: =L20*(1+0.025) -> 245386.41 | N23: =M20*(1+0.02) -> 247852.24 | O23: =N20*(1+0.02) -> 251570.02
B24: Base Case | H24: =G20*(1+0.03) -> 215873.58 | I24: =H20*(1+0.025) -> 224492.8 | J24: =I20*(1+0.025) -> 230105.12 | K24: =J20*(1+0.02) -> 234707.23 | L24: =K20*(1+0.02) -> 239401.37 | M24: =L20*(1+0.015) -> 242992.39 | N24: =M20*(1+0.015) -> 246637.28 | O24: =N20*(1+0.015) -> 250336.84
B25: Worst Case | H25: =G20*(1+0.01) -> 211681.86 | I25: =H20*(1+0.01) -> 221207.54 | J25: =I20*(1+0.01) -> 226737.73 | K25: =J20*(1+0.005) -> 231255.65 | L25: =K20*(1+0.005) -> 235880.76 | M25: =L20*(1+0.005) -> 240598.38 | N25: =M20*(1+0) -> 242992.39 | O25: =N20*(1+0) -> 246637.28
B27: Mac
B28: Mac Revenue | D28: =D4 -> 40177 | E28: =E4 -> 29357 | F28: =F4 -> 29984 | G28: =G4 -> 33708 | H28: =H4 -> 35730.48 | I28: =I4 -> 37517.004 | J28: =J4 -> 39017.684 | K28: =K4 -> 40383.303 | ... O28: =O4 -> 45011.555
B29: % growth | H29: =H13 -> 0.06 | I29: =I13 -> 0.05 | J29: =J13 -> 0.04 | K29: =K13 -> 0.035 | L29: =L13 -> 0.03 | M29: =M13 -> 0.03 | N29: =N13 -> 0.025 | O29: =O13 -> 0.025
B31: Best Case | H31: =G28*(1+0.09) -> 36741.72 | I31: =H28*(1+0.08) -> 38588.918 | J31: =I28*(1+0.07) -> 40143.194 | K31: =J28*(1+0.055) -> 41163.657 | L31: =K28*(1+0.045) -> 42200.552 | M31: =L28*(1+0.04) -> 43258.594 | N31: =M28*(1+0.035) -> 44342.139 | O31: =N28*(1+0.03) -> 45231.124
B32: Base Case | H32: =G28*(1+0.06) -> 35730.48 | I32: =H28*(1+0.05) -> 37517.004 | J32: =I28*(1+0.04) -> 39017.684 | K32: =J28*(1+0.035) -> 40383.303 | L32: =K28*(1+0.03) -> 41594.802 | M32: =L28*(1+0.03) -> 42842.646 | N32: =M28*(1+0.025) -> 43913.712 | O32: =N28*(1+0.025) -> 45011.555
B33: Worst Case | H33: =G28*(1+0.02) -> 34382.16 | I33: =H28*(1+0.015) -> 36266.437 | J33: =I28*(1+0.04) -> 39017.684 | K33: =J28*(1+0.04) -> 40578.392 | L33: =K28*(1+0.04) -> 41998.635 | M33: =L28*(1+0.035) -> 43050.62 | N33: =M28*(1+0.035) -> 44342.139 | O33: =N28*(1+0.025) -> 45011.555
B35: iPad
B36: IPad Revenue | D36: =D5 -> 29292 | E36: =E5 -> 28300 | F36: =F5 -> 26694 | G36: =G5 -> 28023 | H36: =H5 -> 28863.69 | I36: =I5 -> 29440.964 | J36: =J5 -> 29882.578 | K36: =K5 -> 30181.404 | ... O36: =O5 -> 30942.756
B37: % growth | H37: =H14 -> 0.03 | I37: =I14 -> 0.02 | J37: =J14 -> 0.015 | K37: =K14 -> 0.01 | L37: =L14 -> 0.01 | M37: =M14 -> 0.005 | N37: =N14 -> 0.005 | O37: =O14 -> 0.005
B39: Best Case | H39: =G36*(1+0.06) -> 29704.38 | I39: =H36*(1+0.05) -> 30306.875 | J39: =I36*(1+0.04) -> 30618.602 | K39: =J36*(1+0.025) -> 30629.643 | L39: =K36*(1+0.015) -> 30634.125 | M39: =L36*(1+0.012) -> 30849.017 | N39: =M36*(1+0.01) -> 30941.991 | O39: =N36*(1+0.01) -> 31096.7
B40: Base Case | H40: =G36*(1+0.03) -> 28863.69 | I40: =H36*(1+0.02) -> 29440.964 | J40: =I36*(1+0.015) -> 29882.578 | K40: =J36*(1+0.01) -> 30181.404 | L40: =K36*(1+0.01) -> 30483.218 | M40: =L36*(1+0.005) -> 30635.634 | N40: =M36*(1+0.005) -> 30788.812 | O40: =N36*(1+0.005) -> 30942.756
B41: Worst Case | H41: =G36*(1+0.03) -> 28863.69 | I41: =H36*(1+0.01) -> 29152.327 | J41: =I36*(1+0.01) -> 29735.373 | K41: =J36*(1+0.01) -> 30181.404 | L41: =K36*(1+0.005) -> 30332.311 | M41: =L36*(1+0.005) -> 30635.634 | N41: =M36*(1+0.005) -> 30788.812 | O41: =N36*(1+0.005) -> 30942.756
B43: Wearables Home and Accessories
B44: Wearables Home and Accessories Revenue | D44: =D6 -> 41241 | E44: =E6 -> 39845 | F44: =F6 -> 37005 | G44: =G6 -> 35686 | H44: =H6 -> 36042.86 | I44: =I6 -> 36763.717 | J44: =J6 -> 37866.629 | K44: =K6 -> 39002.628 | ... O44: =O6 -> 43897.801
B45: % growth | H45: =H15 -> 0.01 | I45: =I15 -> 0.02 | J45: =J15 -> 0.03 | K45: =K15 -> 0.03 | L45: =L15 -> 0.03 | M45: =M15 -> 0.03 | N45: =N15 -> 0.03 | O45: =O15 -> 0.03
B47: Best Case | H47: =G44*(1+0.025) -> 36578.15 | I47: =H44*(1+0.035) -> 37304.36 | J47: =I44*(1+0.05) -> 38601.903 | K47: =J44*(1+0.05) -> 39759.96 | L47: =K44*(1+0.045) -> 40757.746 | M47: =L44*(1+0.04) -> 41779.615 | N47: =M44*(1+0.04) -> 43033.003 | O47: =N44*(1+0.04) -> 44323.993
B48: Base Case | H48: =G44*(1+0.01) -> 36042.86 | I48: =H44*(1+0.02) -> 36763.717 | J48: =I44*(1+0.03) -> 37866.629 | K48: =J44*(1+0.03) -> 39002.628 | L48: =K44*(1+0.03) -> 40172.706 | M48: =L44*(1+0.03) -> 41377.888 | N48: =M44*(1+0.03) -> 42619.224 | O48: =N44*(1+0.03) -> 43897.801
B49: Worst Case | H49: =G44*(1+(-0.003)) -> 35578.942 | I49: =H44*(1+0.005) -> 36223.074 | J49: =I44*(1+0.005) -> 36947.536 | K49: =J44*(1+0.005) -> 38055.962 | L49: =K44*(1+0.005) -> 39197.641 | M49: =L44*(1+0.005) -> 40373.57 | N49: =M44*(1+0.005) -> 41584.777 | O49: =N44*(1+0.005) -> 42832.32
B51: Services
...

Sheet Income Statement
B2: ="Income Statement of " & Cover!F5 -> Income Statement of Apple Inc.
D3: 2022 | E3: =D3+1 -> 2023 | F3: =E3+1 -> 2024 | G3: =F3+1 -> 2025 | H3: =G3+1 -> 2026 | I3: =H3+1 -> 2027 | J3: =I3+1 -> 2028 | K3: =J3+1 -> 2029 | L3: =K3+1 -> 2030 | ... O3: =N3+1 -> 2033
B4: Figures in millions except number of shares which are reflected in thousands and per-share amounts
B5: Net sales:
B6: Products | D6: 316199 | E6: 298085 | F6: 294866 | G6: 307003 | H6: ='Revenue Build'!H3+'Revenue Build'!H4+'Revenue Build'!H5+'Revenue Build'!H6 -> 319654.4 | I6: ='Revenue Build'!I3+'Revenue Build'!I4+'Revenue Build'!I5+'Revenue Build'!I6 -> 328214.49 | J6: ='Revenue Build'!J3+'Revenue Build'!J4+'Revenue Build'!J5+'Revenue Build'!J6 -> 336872.02 | K6: ='Revenue Build'!K3+'Revenue Build'!K4+'Revenue Build'!K5+'Revenue Build'!K6 -> 344274.56 | L6: ='Revenue Build'!L3+'Revenue Build'!L4+'Revenue Build'!L5+'Revenue Build'!L6 -> 351652.1 | M6: ='Revenue Build'!M3+'Revenue Build'!M4+'Revenue Build'!M5+'Revenue Build'!M6 -> 357848.56 | N6: ='Revenue Build'!N3+'Revenue Build'!N4+'Revenue Build'!N5+'Revenue Build'!N6 -> 363959.03 | O6: ='Revenue Build'!O3+'Revenue Build'!O4+'Revenue Build'!O5+'Revenue Build'!O6 -> 370188.95
B7: Service | D7: 78129 | E7: 85200 | F7: 96169 | G7: 109158 | H7: ='Revenue Build'!H7 -> 124440.12 | I7: ='Revenue Build'!I7 -> 140617.34 | J7: ='Revenue Build'!J7 -> 157491.42 | K7: ='Revenue Build'!K7 -> 174815.47 | L7: ='Revenue Build'!L7 -> 192297.02 | M7: ='Revenue Build'!M7 -> 209603.75 | N7: ='Revenue Build'!N7 -> 228468.09 | O7: ='Revenue Build'!O7 -> 246745.54
B8: Total net sales | D8: =D6+D7 -> 394328 | E8: =E6+E7 -> 383285 | F8: =F6+F7 -> 391035 | G8: =G6+G7 -> 416161 | H8: =H6+H7 -> 444094.52 | I8: =I6+I7 -> 468831.82 | J8: =J6+J7 -> 494363.43 | K8: =K6+K7 -> 519090.03 | ... O8: =O6+O7 -> 616934.48
B10: Cost of Goods | D10: 223546 | E10: 214137 | F10: 210352 | G10: 220960 | H10: =H8*Assumptions!H10 -> 235814.19 | I10: =I8*Assumptions!I10 -> 246136.71 | J10: =J8*Assumptions!J10 -> 256574.62 | K10: =K8*Assumptions!K10 -> 266812.28 | L10: =L8*Assumptions!L10 -> 275782.2 | M10: =M8*Assumptions!M10 -> 284293.61 | N10: =N8*Assumptions!N10 -> 293251.42 | O10: =O8*Assumptions!O10 -> 301680.96
B11: Gross Profit | D11: =D8-D10 -> 170782 | E11: =E8-E10 -> 169148 | F11: =F8-F10 -> 180683 | G11: =G8-G10 -> 195201 | H11: =H8-H10 -> 208280.33 | I11: =I8-I10 -> 222695.12 | J11: =J8-J10 -> 237788.81 | K11: =K8-K10 -> 252277.76 | ... O11: =O8-O10 -> 315253.52
B13: Operating expenses:
B14: Research and development | D14: 26251 | E14: 29915 | F14: 31370 | G14: 34550 | H14: =H8*Assumptions!G12 -> 35527.562 | I14: =I8*Assumptions!H12 -> 37975.378 | J14: =J8*Assumptions!I12 -> 40537.801 | K14: =K8*Assumptions!J12 -> 43084.473 | L14: =L8*Assumptions!K12 -> 45691.726 | M14: =M8*Assumptions!L12 -> 48233.446 | N14: =N8*Assumptions!M12 -> 50948.732 | O14: =O8*Assumptions!N12 -> 53673.3
B15: Selling general and administrative | D15: 25094 | E15: 24932 | F15: 26097 | G15: 27601 | H15: =H8*Assumptions!G13 -> 29310.238 | I15: =I8*Assumptions!H13 -> 30474.069 | J15: =J8*Assumptions!I13 -> 32133.623 | K15: =K8*Assumptions!J13 -> 33740.852 | L15: =L8*Assumptions!K13 -> 35356.693 | M15: =M8*Assumptions!L13 -> 36884.4 | N15: =N8*Assumptions!M13 -> 38507.762 | O15: =O8*Assumptions!N13 -> 40100.742
B16: Total operating expenses | D16: =D14+D15 -> 51345 | E16: =E14+E15 -> 54847 | F16: =F14+F15 -> 57467 | G16: =G14+G15 -> 62151 | H16: =H14+H15 -> 64837.8 | I16: =I14+I15 -> 68449.446 | J16: =J14+J15 -> 72671.424 | K16: =K14+K15 -> 76825.325 | ... O16: =O14+O15 -> 93774.042
B18: EBIT (Operating income) | D18: =D11-D16 -> 119437 | E18: =E11-E16 -> 114301 | F18: =F11-F16 -> 123216 | G18: =G11-G16 -> 133050 | H18: =H11-H16 -> 143442.53 | I18: =I11-I16 -> 154245.67 | J18: =J11-J16 -> 165117.39 | K18: =K11-K16 -> 175452.43 | ... O18: =O11-O16 -> 221479.48
B19: Other income/(expense) net | D19: -334 | E19: -565 | F19: 269 | G19: -321 | H19: =H8*Assumptions!G16 -> -355.27562 | I19: =I8*Assumptions!H16 -> -375.06546 | J19: =J8*Assumptions!I16 -> -395.49075 | K19: =K8*Assumptions!J16 -> -415.27203 | L19: =L8*Assumptions!K16 -> -435.15929 | M19: =M8*Assumptions!L16 -> -453.96185 | N19: =N8*Assumptions!M16 -> -473.94169 | O19: =O8*Assumptions!N16 -> -493.54759
B20: Income before provision for income taxes | D20: =D18+D19 -> 119103 | E20: =E18+E19 -> 113736 | F20: =F18+F19 -> 123485 | G20: =G18+G19 -> 132729 | H20: =H18+H19 -> 143087.25 | I20: =I18+I19 -> 153870.6 | J20: =J18+J19 -> 164721.9 | K20: =K18+K19 -> 175037.16 | ... O20: =O18+O19 -> 220985.93
B21: Provision for income taxes | D21: 19300 | E21: 16741 | F21: 29749 | G21: 20719 | H21: =H20*Assumptions!H18 -> 22893.961 | I21: =I20*Assumptions!I18 -> 24619.297 | J21: =J20*Assumptions!J18 -> 26355.503 | K21: =K20*Assumptions!K18 -> 28005.945 | L21: =L20*Assumptions!L18 -> 29869.334 | M21: =M20*Assumptions!M18 -> 31613.903 | N21: =N20*Assumptions!N18 -> 33479.241 | O21: =O20*Assumptions!O18 -> 35357.749
B22: Net Income | D22: =D20-D21 -> 99803 | E22: =E20-E21 -> 96995 | F22: =F20-F21 -> 93736 | G22: =G20-G21 -> 112010 | H22: =H20-H21 -> 120193.29 | I22: =I20-I21 -> 129251.31 | J22: =J20-J21 -> 138366.39 | K22: =K20-K21 -> 147031.21 | ... O22: =O20-O21 -> 185628.18
B24: Depreciation and amortization | D24: ='Cash Flow Statements'!D9 -> 11104 | E24: ='Cash Flow Statements'!E9 -> 11519 | F24: ='Cash Flow Statements'!F9 -> 11445 | G24: ='Cash Flow Statements'!G9 -> 11698 | H24: =H8*Assumptions!H$22 -> 12434.647 | I24: =I8*Assumptions!I$22 -> 13127.291 | J24: =J8*Assumptions!J$22 -> 13842.176 | K24: =K8*Assumptions!K$22 -> 14534.521 | L24: =L8*Assumptions!L$22 -> 15230.575 | M24: =M8*Assumptions!M$22 -> 15888.665 | N24: =N8*Assumptions!N$22 -> 16587.959 | O24: =O8*Assumptions!O$22 -> 17274.166
B25: EBITDA | D25: =D18+D24 -> 130541 | E25: =E18+E24 -> 125820 | F25: =F18+F24 -> 134661 | G25: =G18+G24 -> 144748 | H25: =H18+H24 -> 155877.18 | I25: =I18+I24 -> 167372.96 | J25: =J18+J24 -> 178959.56 | K25: =K18+K24 -> 189986.95 | ... O25: =O18+O24 -> 238753.65
B26: Share-based compensation expense | D26: ='Cash Flow Statements'!D10 -> 9038 | E26: ='Cash Flow Statements'!E10 -> 10833 | F26: ='Cash Flow Statements'!F10 -> 11688 | G26: ='Cash Flow Statements'!G10 -> 12863 | H26: ='Cash Flow Statements'!H10 -> 13766.93 | I26: ='Cash Flow Statements'!I10 -> 14533.787 | J26: ='Cash Flow Statements'!J10 -> 15325.266 | K26: ='Cash Flow Statements'!K10 -> 16091.791 | ... O26: ='Cash Flow Statements'!O10 -> 19124.969
B27: Adjusted EBITDA | D27: =D25+D26 -> 139579 | E27: =E25+E26 -> 136653 | F27: =F25+F26 -> 146349 | G27: =G25+G26 -> 157611 | H27: =H25+H26 -> 169644.11 | I27: =I25+I26 -> 181906.75 | J27: =J25+J26 -> 194284.83 | K27: =K25+K26 -> 206078.74 | ... O27: =O25+O26 -> 257878.61
B29: Earnings per share:
B30: Basic | D30: 6.15 | E30: 6.16 | F30: 6.11 | G30: 7.49 | H30: =H22/H34 -> 8.2891669 | I30: =I22/I34 -> 9.1895419 | J30: =J22/J34 -> 10.141864 | K30: =K22/K34 -> 11.11028 | L30: =L22/L34 -> 12.215987 | M30: =M22/M34 -> 13.329363 | N30: =N22/N34 -> 14.552418 | O30: =O22/O34 -> 15.844277
B31: Diluted | D31: 6.11 | E31: 6.13 | F31: 6.08 | G31: 7.46 | H31: =H22/H35 -> 8.2315461 | I31: =I22/I35 -> 9.1256623 | J31: =J22/J35 -> 10.071365 | K31: =K22/K35 -> 11.033048 | L31: =L22/L35 -> 12.131069 | M31: =M22/M35 -> 13.236706 | N31: =N22/N35 -> 14.451259 | O31: =O22/O35 -> 15.734138
B33: Shares used in computing earnings per share:
B34: Basic | D34: 16215.963 | E34: 15744.231 | F34: 15343.783 | G34: 14948.5 | H34: =G34*(1-Assumptions!H29) -> 14500.045 | I34: =H34*(1-Assumptions!I29) -> 14065.044 | J34: =I34*(1-Assumptions!J29) -> 13643.092 | K34: =J34*(1-Assumptions!K29) -> 13233.8 | L34: =K34*(1-Assumptions!L29) -> 12836.786 | M34: =L34*(1-Assumptions!M29) -> 12451.682 | N34: =M34*(1-Assumptions!N29) -> 12078.132 | O34: =N34*(1-Assumptions!O29) -> 11715.788
B35: Diluted | D35: 16325.819 | E35: 15812.547 | F35: 15408.095 | G35: 15004.697 | H35: =H34*(1+Assumptions!H30) -> 14601.545 | I35: =I34*(1+Assumptions!I30) -> 14163.499 | J35: =J34*(1+Assumptions!J30) -> 13738.594 | K35: =K34*(1+Assumptions!K30) -> 13326.436 | L35: =L34*(1+Assumptions!L30) -> 12926.643 | M35: =M34*(1+Assumptions!M30) -> 12538.844 | N35: =N34*(1+Assumptions!N30) -> 12162.678 | O35: =O34*(1+Assumptions!O30) -> 11797.798

Sheet Balance Sheet
B2: ="Balance sheet of " &Cover!F5 -> Balance sheet of Apple Inc.
D3: 2022 | E3: =D3+1 -> 2023 | F3: =E3+1 -> 2024 | G3: =F3+1 -> 2025 | H3: =G3+1 -> 2026 | I3: =H3+1 -> 2027 | J3: =I3+1 -> 2028 | K3: =J3+1 -> 2029 | L3: =K3+1 -> 2030 | ... O3: =N3+1 -> 2033
B5: ASSETS:
B6: Current assets:
B7: Cash and cash equivalents | D7: 23646 | E7: 29965 | F7: 29943 | G7: 35934 | H7: ='Cash Flow Statements'!H40 -> 45173.3 | I7: ='Cash Flow Statements'!I40 -> 68403.499 | J7: ='Cash Flow Statements'!J40 -> 105685.97 | K7: ='Cash Flow Statements'!K40 -> 159917.98 | L7: ='Cash Flow Statements'!L40 -> 228001.01 | M7: ='Cash Flow Statements'!M40 -> 306150.71 | N7: ='Cash Flow Statements'!N40 -> 398241.17 | O7: ='Cash Flow Statements'!O40 -> 504238.73
B8: Marketable securities | D8: 24658 | E8: 31590 | F8: 35228 | G8: 18763 | H8: =G8*(1+Assumptions!$D$38) -> 18387.74 | I8: =H8*(1+Assumptions!$D$38) -> 18019.985 | J8: =I8*(1+Assumptions!$D$38) -> 17659.585 | K8: =J8*(1+Assumptions!$D$38) -> 17306.394 | L8: =K8*(1+Assumptions!$D$38) -> 16960.266 | M8: =L8*(1+Assumptions!$D$38) -> 16621.061 | N8: =M8*(1+Assumptions!$D$38) -> 16288.639 | O8: =N8*(1+Assumptions!$D$38) -> 15962.867
B9: Accounts receivable net | D9: 28184 | E9: 29508 | F9: 33410 | G9: 39777 | H9: ='Income Statement'!H8*Assumptions!H24/365 -> 42584.406 | I9: ='Income Statement'!I8*Assumptions!I24/365 -> 44956.476 | J9: ='Income Statement'!J8*Assumptions!J24/365 -> 47404.713 | K9: ='Income Statement'!K8*Assumptions!K24/365 -> 49775.757 | L9: ='Income Statement'!L8*Assumptions!L24/365 -> 52159.504 | M9: ='Income Statement'!M8*Assumptions!M24/365 -> 54413.235 | N9: ='Income Statement'!N8*Assumptions!N24/365 -> 56808.08 | O9: ='Income Statement'!O8*Assumptions!O24/365 -> 59158.101
B10: Vendor non-trade receivables | D10: 32748 | E10: 31477 | F10: 32833 | G10: 33180 | H10: =G10*(1+Assumptions!$D$39) -> 33345.9 | I10: =H10*(1+Assumptions!$D$39) -> 33512.629 | J10: =I10*(1+Assumptions!$D$39) -> 33680.193 | K10: =J10*(1+Assumptions!$D$39) -> 33848.594 | L10: =K10*(1+Assumptions!$D$39) -> 34017.837 | M10: =L10*(1+Assumptions!$D$39) -> 34187.926 | N10: =M10*(1+Assumptions!$D$39) -> 34358.865 | O10: =N10*(1+Assumptions!$D$39) -> 34530.66
B11: Inventories | D11: 4946 | E11: 6331 | F11: 7286 | G11: 5718 | H11: ='Income Statement'!H10*Assumptions!H$25/365 -> 5814.5965 | I11: ='Income Statement'!I10*Assumptions!I$25/365 -> 6069.1243 | J11: ='Income Statement'!J10*Assumptions!J$25/365 -> 6326.4975 | K11: ='Income Statement'!K10*Assumptions!K$25/365 -> 6578.9329 | L11: ='Income Statement'!L10*Assumptions!L$25/365 -> 6800.1091 | M11: ='Income Statement'!M10*Assumptions!M$25/365 -> 7009.9794 | N11: ='Income Statement'!N10*Assumptions!N$25/365 -> 7230.857 | O11: ='Income Statement'!O10*Assumptions!O$25/365 -> 7438.7087
B12: Other current assets | D12: 21223 | E12: 14695 | F12: 14287 | G12: 14585 | H12: =G12*(1+Assumptions!$D$40) -> 14876.7 | I12: =H12*(1+Assumptions!$D$40) -> 15174.234 | J12: =I12*(1+Assumptions!$D$40) -> 15477.719 | K12: =J12*(1+Assumptions!$D$40) -> 15787.273 | L12: =K12*(1+Assumptions!$D$40) -> 16103.019 | M12: =L12*(1+Assumptions!$D$40) -> 16425.079 | N12: =M12*(1+Assumptions!$D$40) -> 16753.58 | O12: =N12*(1+Assumptions!$D$40) -> 17088.652
B13: Total current assets | D13: =SUM(D7:D12) -> 135405 | E13: =SUM(E7:E12) -> 143566 | F13: =SUM(F7:F12) -> 152987 | G13: =SUM(G7:G12) -> 147957 | H13: =SUM(H7:H12) -> 160182.64 | I13: =SUM(I7:I12) -> 186135.95 | J13: =SUM(J7:J12) -> 226234.68 | K13: =SUM(K7:K12) -> 283214.93 | ... O13: =SUM(O7:O12) -> 638417.71
B15: Non-current assets:
B16: Marketable securities | D16: 120805 | E16: 100544 | F16: 91479 | G16: 77723 | H16: =G16*(1+Assumptions!$D$38) -> 76168.54 | I16: =H16*(1+Assumptions!$D$38) -> 74645.169 | J16: =I16*(1+Assumptions!$D$38) -> 73152.266 | K16: =J16*(1+Assumptions!$D$38) -> 71689.22 | L16: =K16*(1+Assumptions!$D$38) -> 70255.436 | M16: =L16*(1+Assumptions!$D$38) -> 68850.327 | N16: =M16*(1+Assumptions!$D$38) -> 67473.321 | O16: =N16*(1+Assumptions!$D$38) -> 66123.854
B17: Property plant and equipment net | D17: 42117 | E17: 43715 | F17: 45680 | G17: 49834 | H17: =Schedules!H32 -> 54877.271 | I17: =Schedules!I32 -> 60521.649 | J17: =Schedules!J32 -> 66788.608 | K17: =Schedules!K32 -> 73649.984 | L17: =Schedules!L32 -> 81106.614 | M17: =Schedules!M32 -> 89113.132 | N17: =Schedules!N32 -> 97711.764 | O17: =Schedules!O32 -> 106884.56
B18: Other non-current assets | D18: 54428 | E18: 64758 | F18: 74834 | G18: 83727 | H18: =G18*(1+Assumptions!$D$40) -> 85401.54 | I18: =H18*(1+Assumptions!$D$40) -> 87109.571 | J18: =I18*(1+Assumptions!$D$40) -> 88851.762 | K18: =J18*(1+Assumptions!$D$40) -> 90628.797 | L18: =K18*(1+Assumptions!$D$40) -> 92441.373 | M18: =L18*(1+Assumptions!$D$40) -> 94290.201 | N18: =M18*(1+Assumptions!$D$40) -> 96176.005 | O18: =N18*(1+Assumptions!$D$40) -> 98099.525
B19: Total non-current assets | D19: =SUM(D16:D18) -> 217350 | E19: =SUM(E16:E18) -> 209017 | F19: =SUM(F16:F18) -> 211993 | G19: =SUM(G16:G18) -> 211284 | H19: =SUM(H16:H18) -> 216447.35 | I19: =SUM(I16:I18) -> 222276.39 | J19: =SUM(J16:J18) -> 228792.64 | K19: =SUM(K16:K18) -> 235968 | ... O19: =SUM(O16:O18) -> 271107.94
B20: Total assets | D20: =D13+D19 -> 352755 | E20: =E13+E19 -> 352583 | F20: =F13+F19 -> 364980 | G20: =G13+G19 -> 359241 | H20: =H13+H19 -> 376629.99 | I20: =I13+I19 -> 408412.34 | J20: =J13+J19 -> 455027.31 | K20: =K13+K19 -> 519182.94 | ... O20: =O13+O19 -> 909525.65
B22: LIABILITIES AND SHAREHOLDERS’ EQUITY:
B23: Current liabilities:
B24: Accounts payable | D24: 64115 | E24: 62611 | F24: 68960 | G24: 69860 | H24: ='Income Statement'!H10*Assumptions!H$26/365 -> 74297.622 | I24: ='Income Statement'!I10*Assumptions!I$26/365 -> 77549.922 | J24: ='Income Statement'!J10*Assumptions!J$26/365 -> 80838.579 | K24: ='Income Statement'!K10*Assumptions!K$26/365 -> 84064.142 | L24: ='Income Statement'!L10*Assumptions!L$26/365 -> 86890.283 | M24: ='Income Statement'!M10*Assumptions!M$26/365 -> 89571.959 | N24: ='Income Statement'!N10*Assumptions!N$26/365 -> 92394.284 | O24: ='Income Statement'!O10*Assumptions!O$26/365 -> 95050.166
B25: Other current liabilities | D25: 60845 | E25: 58829 | F25: 78304 | G25: 66387 | H25: =G25*(1+Assumptions!$D$42) -> 67714.74 | I25: =H25*(1+Assumptions!$D$42) -> 69069.035 | J25: =I25*(1+Assumptions!$D$42) -> 70450.415 | K25: =J25*(1+Assumptions!$D$42) -> 71859.424 | L25: =K25*(1+Assumptions!$D$42) -> 73296.612 | M25: =L25*(1+Assumptions!$D$42) -> 74762.545 | N25: =M25*(1+Assumptions!$D$42) -> 76257.795 | O25: =N25*(1+Assumptions!$D$42) -> 77782.951
B26: Deferred revenue | D26: 7912 | E26: 8061 | F26: 8249 | G26: 9055 | H26: =G26*(1+Assumptions!$D$43) -> 9960.5 | I26: =H26*(1+Assumptions!$D$43) -> 10956.55 | J26: =I26*(1+Assumptions!$D$43) -> 12052.205 | K26: =J26*(1+Assumptions!$D$43) -> 13257.426 | L26: =K26*(1+Assumptions!$D$43) -> 14583.168 | M26: =L26*(1+Assumptions!$D$43) -> 16041.485 | N26: =M26*(1+Assumptions!$D$43) -> 17645.633 | O26: =N26*(1+Assumptions!$D$43) -> 19410.197
B27: Commercial paper | D27: 9982 | E27: 5985 | F27: 9967 | G27: 7979 | H27: =G27 -> 7979 | I27: =H27 -> 7979 | J27: =I27 -> 7979 | K27: =J27 -> 7979 | L27: =K27 -> 7979 | M27: =L27 -> 7979 | N27: =M27 -> 7979 | O27: =N27 -> 7979
B28: Term debt | D28: 11128 | E28: 9822 | F28: 10912 | G28: 12350 | H28: =Schedules!I48 -> 10078 | I28: =Schedules!J48 -> 9300 | J28: =Schedules!K48 -> 5235 | K28: =Schedules!L48 -> 4972 | L28: =Schedules!M48 -> 8254 | M28: =Schedules!N48 -> 8254 | N28: =Schedules!O48 -> 8254
B29: Total current liabilities | D29: =SUM(D24:D28) -> 153982 | E29: =SUM(E24:E28) -> 145308 | F29: =SUM(F24:F28) -> 176392 | G29: =SUM(G24:G28) -> 165631 | H29: =SUM(H24:H28) -> 170029.86 | I29: =SUM(I24:I28) -> 174854.51 | J29: =SUM(J24:J28) -> 176555.2 | K29: =SUM(K24:K28) -> 182131.99 | ... O29: =SUM(O24:O28) -> 200222.31
B31: Non-current liabilities:
B32: Term debt | D32: 98959 | E32: 95281 | F32: 85750 | G32: 78328 | H32: =Schedules!H50-'Balance Sheet'!H28 -> 68207 | I32: =Schedules!I50-'Balance Sheet'!I28 -> 58907 | J32: =Schedules!J50-'Balance Sheet'!J28 -> 53672 | K32: =Schedules!K50-'Balance Sheet'!K28 -> 48700 | L32: =Schedules!L50-'Balance Sheet'!L28 -> 40446 | M32: =Schedules!M50-'Balance Sheet'!M28 -> 32192 | N32: =Schedules!N50-'Balance Sheet'!N28 -> 23938 | O32: =Schedules!O50-'Balance Sheet'!O28 -> 23938
B33: Other non-current liabilities | D33: 49142 | E33: 49848 | F33: 45888 | G33: 41549 | H33: =G33*(1+Assumptions!$D$42) -> 42379.98 | I33: =H33*(1+Assumptions!$D$42) -> 43227.58 | J33: =I33*(1+Assumptions!$D$42) -> 44092.131 | K33: =J33*(1+Assumptions!$D$42) -> 44973.974 | L33: =K33*(1+Assumptions!$D$42) -> 45873.453 | M33: =L33*(1+Assumptions!$D$42) -> 46790.922 | N33: =M33*(1+Assumptions!$D$42) -> 47726.741 | O33: =N33*(1+Assumptions!$D$42) -> 48681.276
B34: Total non-current liabilities | D34: =D32+D33 -> 148101 | E34: =E32+E33 -> 145129 | F34: =SUM(F32:F33) -> 131638 | G34: =SUM(G32:G33) -> 119877 | H34: =SUM(H32:H33) -> 110586.98 | I34: =SUM(I32:I33) -> 102134.58 | J34: =SUM(J32:J33) -> 97764.131 | K34: =SUM(K32:K33) -> 93673.974 | L34: =SUM(L32:L33) -> 86319.453 | M34: =SUM(M32:M33) -> 78982.922 | ... O34: =SUM(O32:O33) -> 72619.276
B35: Total liabilities | D35: =D29+D34 -> 302083 | E35: =E29+E34 -> 290437 | F35: =F29+F34 -> 308030 | G35: =G29+G34 -> 285508 | H35: =H29+H34 -> 280616.84 | I35: =I29+I34 -> 276989.09 | J35: =J29+J34 -> 274319.33 | K35: =K29+K34 -> 275805.97 | ... O35: =O29+O34 -> 272841.59
B37: Commitments and contingencies
B39: Shareholders’ equity:
B40: Common stock and additional paid-in capital $0.00001 par value: 50400000 shares authorized; 14939315 and 15116786 shares issued and outstanding respectively | D40: 64849 | E40: 73812 | F40: 83276 | G40: 93568 | H40: =G40+Schedules!H87-Schedules!H88 -> 100984.38 | I40: =H40+Schedules!I87-Schedules!I88 -> 108813.87 | J40: =I40+Schedules!J87-Schedules!J88 -> 117069.74 | K40: =J40+Schedules!K87-Schedules!K88 -> 125738.54 | L40: =K40+Schedules!L87-Schedules!L88 -> 134822.49 | M40: =L40+Schedules!M87-Schedules!M88 -> 144298.95 | N40: =M40+Schedules!N87-Schedules!N88 -> 154192.48 | O40: =N40+Schedules!O87-Schedules!O88 -> 164495.29
B41: Accumulated deficit | D41: -3068 | E41: -214 | F41: -19154 | G41: -14264 | H41: =G41+'Income Statement'!H22-Assumptions!H44-Assumptions!H46 -> 599.77365 | I41: =H41+'Income Statement'!I$22-Assumptions!I$44-Assumptions!I$46 -> 28180.381 | J41: =I41+'Income Statement'!J$22-Assumptions!J$44-Assumptions!J$46 -> 69209.244 | K41: =J41+'Income Statement'!K$22-Assumptions!K$44-Assumptions!K$46 -> 123209.43 | L41: =K41+'Income Statement'!L$22-Assumptions!L$44-Assumptions!L$46 -> 191271.16 | M41: =L41+'Income Statement'!M$22-Assumptions!M$44-Assumptions!M$46 -> 272741.79 | N41: =M41+'Income Statement'!N$22-Assumptions!N$44-Assumptions!N$46 -> 368225.35 | O41: =N41+'Income Statement'!O$22-Assumptions!O$44-Assumptions!O$46 -> 477759.78
B42: Accumulated other comprehensive loss | D42: -11109 | E42: -11452 | F42: -7172 | G42: -5571 | H42: =G42 -> -5571 | I42: =H42 -> -5571 | J42: =I42 -> -5571 | K42: =J42 -> -5571 | L42: =K42 -> -5571 | M42: =L42 -> -5571 | N42: =M42 -> -5571 | O42: =N42 -> -5571
B43: Total shareholders’ equity | D43: =D40+D41+D42 -> 50672 | E43: =E40+E41+E42 -> 62146 | F43: =SUM(F40:F42) -> 56950 | G43: =SUM(G40:G42) -> 73733 | H43: =SUM(H40:H42) -> 96013.152 | I43: =SUM(I40:I42) -> 131423.25 | J43: =SUM(J40:J42) -> 180707.98 | K43: =SUM(K40:K42) -> 243376.97 | L43: =SUM(L40:L42) -> 320522.65 | M43: =SUM(M40:M42) -> 411469.74 | ... O43: =SUM(O40:O42) -> 636684.06
B46: Balance check | D46: =D20-D35-D43 -> 0 | E46: =E20-E35-E43 -> 0 | F46: =F20-F35-F43 -> 0 | G46: =G20-G35-G43 -> 0 | H46: =H20-H35-H43 -> 0 | I46: =I20-I35-I43 -> 0 | J46: =J20-J35-J43 -> 0 | K46: =K20-K35-K43 -> 0 | ... O46: =O20-O35-O43 -> 0

Sheet Cash Flow Statements
B2: ="Cash Flow Statement of " & Cover!F5 -> Cash Flow Statement of Apple Inc.
D3: 2022 | E3: =D3+1 -> 2023 | F3: =E3+1 -> 2024 | G3: =F3+1 -> 2025 | H3: =G3+1 -> 2026 | I3: =H3+1 -> 2027 | J3: =I3+1 -> 2028 | K3: =J3+1 -> 2029 | L3: =K3+1 -> 2030 | ... O3: =N3+1 -> 2033
B4: Cash cash equivalents and restricted cash and cash equivalents beginning balances | D4: 35929 | E4: 24977 | F4: 30737 | G4: 29943 | H4: ='Balance Sheet'!G$7 -> 35934 | I4: =H40 -> 45173.3 | J4: =I40 -> 68403.499 | K4: =J40 -> 105685.97 | L4: =K40 -> 159917.98 | M4: =L40 -> 228001.01 | N4: =M40 -> 306150.71 | O4: =N40 -> 398241.17
B6: Operating activities:
B7: Net income | D7: 99803 | E7: 96995 | F7: 93736 | G7: 112010 | H7: ='Income Statement'!H22 -> 120193.29 | I7: ='Income Statement'!I22 -> 129251.31 | J7: ='Income Statement'!J22 -> 138366.39 | K7: ='Income Statement'!K22 -> 147031.21 | L7: ='Income Statement'!L22 -> 156814 | M7: ='Income Statement'!M22 -> 165972.99 | N7: ='Income Statement'!N22 -> 175766.02 | O7: ='Income Statement'!O22 -> 185628.18
B8: Adjustments to reconcile net income to cash generated by operating activities:
B9: Depreciation and amortization | D9: 11104 | E9: 11519 | F9: 11445 | G9: 11698 | H9: =Schedules!H31 -> 8723.659 | I9: =Schedules!I31 -> 8889.4085 | J9: =Schedules!J31 -> 9058.3073 | K9: =Schedules!K31 -> 9230.4151 | L9: =Schedules!L31 -> 9405.793 | M9: =Schedules!M31 -> 9584.5031 | N9: =Schedules!N31 -> 9766.6086 | O9: =Schedules!O31 -> 9952.1742
B10: Share-based compensation expense | D10: 9038 | E10: 10833 | F10: 11688 | G10: 12863 | H10: ='Income Statement'!H$8*Assumptions!H$48 -> 13766.93 | I10: ='Income Statement'!I$8*Assumptions!I$48 -> 14533.787 | J10: ='Income Statement'!J$8*Assumptions!J$48 -> 15325.266 | K10: ='Income Statement'!K$8*Assumptions!K$48 -> 16091.791 | L10: ='Income Statement'!L$8*Assumptions!L$48 -> 16862.423 | M10: ='Income Statement'!M$8*Assumptions!M$48 -> 17591.022 | N10: ='Income Statement'!N$8*Assumptions!N$48 -> 18365.241 | O10: ='Income Statement'!O$8*Assumptions!O$48 -> 19124.969 | P10: Source: Apple 10-K FY2025 p.29 — SBC $12,863M; projected at 3.1% of revenue
B11: Other | D11: 1006 | E11: -2227 | F11: -2266 | G11: -89 | H11: =0 -> 0 | I11: =0 -> 0 | J11: =0 -> 0 | K11: =0 -> 0 | L11: =0 -> 0 | M11: =0 -> 0 | N11: =0 -> 0 | O11: =0 -> 0
B12: Changes in operating assets and liabilities:
B13: Accounts receivable net | D13: -1823 | E13: -1688 | F13: -3788 | G13: -6682 | H13: =-('Balance Sheet'!H$9-'Balance Sheet'!G$9) -> -2807.406 | I13: =-('Balance Sheet'!I$9-'Balance Sheet'!H$9) -> -2372.0703 | J13: =-('Balance Sheet'!J$9-'Balance Sheet'!I$9) -> -2448.2362 | K13: =-('Balance Sheet'!K$9-'Balance Sheet'!J$9) -> -2371.044 | L13: =-('Balance Sheet'!L$9-'Balance Sheet'!K$9) -> -2383.7477 | M13: =-('Balance Sheet'!M$9-'Balance Sheet'!L$9) -> -2253.7309 | N13: =-('Balance Sheet'!N$9-'Balance Sheet'!M$9) -> -2394.8443 | O13: =-('Balance Sheet'!O$9-'Balance Sheet'!N$9) -> -2350.0218
B14: Vendor non-trade receivables | D14: -7520 | E14: 1271 | F14: -1356 | G14: -347 | H14: =-('Balance Sheet'!H$10-'Balance Sheet'!G$10) -> -165.9 | I14: =-('Balance Sheet'!I$10-'Balance Sheet'!H$10) -> -166.7295 | J14: =-('Balance Sheet'!J$10-'Balance Sheet'!I$10) -> -167.56315 | K14: =-('Balance Sheet'!K$10-'Balance Sheet'!J$10) -> -168.40096 | L14: =-('Balance Sheet'!L$10-'Balance Sheet'!K$10) -> -169.24297 | M14: =-('Balance Sheet'!M$10-'Balance Sheet'!L$10) -> -170.08918 | N14: =-('Balance Sheet'!N$10-'Balance Sheet'!M$10) -> -170.93963 | O14: =-('Balance Sheet'!O$10-'Balance Sheet'!N$10) -> -171.79433
B15: Inventories | D15: 1484 | E15: -1618 | F15: -1046 | G15: 1400 | H15: =-('Balance Sheet'!H11-'Balance Sheet'!G11) -> -96.596469 | I15: =-('Balance Sheet'!I11-'Balance Sheet'!H11) -> -254.52784 | J15: =-('Balance Sheet'!J11-'Balance Sheet'!I11) -> -257.37319 | K15: =-('Balance Sheet'!K11-'Balance Sheet'!J11) -> -252.43536 | L15: =-('Balance Sheet'!L11-'Balance Sheet'!K11) -> -221.17624 | M15: =-('Balance Sheet'!M11-'Balance Sheet'!L11) -> -209.87027 | N15: =-('Balance Sheet'!N11-'Balance Sheet'!M11) -> -220.87761 | O15: =-('Balance Sheet'!O11-'Balance Sheet'!N11) -> -207.8517
B16: Other current and non-current assets | D16: -6499 | E16: -5684 | F16: -11731 | G16: -9197 | H16: =-('Balance Sheet'!H12-'Balance Sheet'!G12)-('Balance Sheet'!H18-'Balance Sheet'!G18) -> -1966.24 | I16: =-('Balance Sheet'!I12-'Balance Sheet'!H12)-('Balance Sheet'!I18-'Balance Sheet'!H18) -> -2005.5648 | J16: =-('Balance Sheet'!J12-'Balance Sheet'!I12)-('Balance Sheet'!J18-'Balance Sheet'!I18) -> -2045.6761 | K16: =-('Balance Sheet'!K12-'Balance Sheet'!J12)-('Balance Sheet'!K18-'Balance Sheet'!J18) -> -2086.5896 | L16: =-('Balance Sheet'!L12-'Balance Sheet'!K12)-('Balance Sheet'!L18-'Balance Sheet'!K18) -> -2128.3214 | M16: =-('Balance Sheet'!M12-'Balance Sheet'!L12)-('Balance Sheet'!M18-'Balance Sheet'!L18) -> -2170.8878 | N16: =-('Balance Sheet'!N12-'Balance Sheet'!M12)-('Balance Sheet'!N18-'Balance Sheet'!M18) -> -2214.3056 | O16: =-('Balance Sheet'!O12-'Balance Sheet'!N12)-('Balance Sheet'!O18-'Balance Sheet'!N18) -> -2258.5917
B17: Accounts payable | D17: 9448 | E17: -1889 | F17: 6020 | G17: 902 | H17: ='Balance Sheet'!H24-'Balance Sheet'!G24 -> 4437.6215 | I17: ='Balance Sheet'!I24-'Balance Sheet'!H24 -> 3252.3002 | J17: ='Balance Sheet'!J24-'Balance Sheet'!I24 -> 3288.6575 | K17: ='Balance Sheet'!K24-'Balance Sheet'!J24 -> 3225.5629 | L17: ='Balance Sheet'!L24-'Balance Sheet'!K24 -> 2826.1408 | M17: ='Balance Sheet'!M24-'Balance Sheet'!L24 -> 2681.6756 | N17: ='Balance Sheet'!N24-'Balance Sheet'!M24 -> 2822.3251 | O17: ='Balance Sheet'!O24-'Balance Sheet'!N24 -> 2655.8828
B18: Other current and non-current liabilities | D18: 6110 | E18: 3031 | F18: 15552 | G18: -11076 | H18: =('Balance Sheet'!H25-'Balance Sheet'!G25)+('Balance Sheet'!H26-'Balance Sheet'!G26)+('Balance Sheet'!H33-'Balance Sheet'!G33) -> 3064.22 | I18: =('Balance Sheet'!I25-'Balance Sheet'!H25)+('Balance Sheet'!I26-'Balance Sheet'!H26)+('Balance Sheet'!I33-'Balance Sheet'!H33) -> 3197.9444 | J18: =('Balance Sheet'!J25-'Balance Sheet'!I25)+('Balance Sheet'!J26-'Balance Sheet'!I26)+('Balance Sheet'!J33-'Balance Sheet'!I33) -> 3341.5873 | K18: =('Balance Sheet'!K25-'Balance Sheet'!J25)+('Balance Sheet'!K26-'Balance Sheet'!J26)+('Balance Sheet'!K33-'Balance Sheet'!J33) -> 3496.0714 | L18: =('Balance Sheet'!L25-'Balance Sheet'!K25)+('Balance Sheet'!L26-'Balance Sheet'!K26)+('Balance Sheet'!L33-'Balance Sheet'!K33) -> 3662.4105 | M18: =('Balance Sheet'!M25-'Balance Sheet'!L25)+('Balance Sheet'!M26-'Balance Sheet'!L26)+('Balance Sheet'!M33-'Balance Sheet'!L33) -> 3841.7181 | N18: =('Balance Sheet'!N25-'Balance Sheet'!M25)+('Balance Sheet'!N26-'Balance Sheet'!M26)+('Balance Sheet'!N33-'Balance Sheet'!M33) -> 4035.2178 | O18: =('Balance Sheet'!O25-'Balance Sheet'!N25)+('Balance Sheet'!O26-'Balance Sheet'!N26)+('Balance Sheet'!O33-'Balance Sheet'!N33) -> 4244.2541
B19: Cash generated by operating activities | D19: =SUM(D7:D18) -> 122151 | E19: =SUM(E7:E18) -> 110543 | F19: =SUM(F7:F18) -> 118254 | G19: =SUM(G7:G18) -> 111482 | H19: =SUM(H7:H18) -> 145149.58 | I19: =SUM(I7:I18) -> 154325.86 | J19: =SUM(J7:J18) -> 164461.36 | K19: =SUM(K7:K18) -> 174196.58 | ... O19: =SUM(O7:O18) -> 216617.2
B21: Investing activities:
B22: Purchases of marketable securities | D22: -76923 | E22: -29513 | F22: -48656 | G22: -24407 | H22: =-('Balance Sheet'!H8-'Balance Sheet'!G8)-('Balance Sheet'!H16-'Balance Sheet'!G16) -> 1929.72 | I22: =-('Balance Sheet'!I8-'Balance Sheet'!H8)-('Balance Sheet'!I16-'Balance Sheet'!H16) -> 1891.1256 | J22: =-('Balance Sheet'!J8-'Balance Sheet'!I8)-('Balance Sheet'!J16-'Balance Sheet'!I16) -> 1853.3031 | K22: =-('Balance Sheet'!K8-'Balance Sheet'!J8)-('Balance Sheet'!K16-'Balance Sheet'!J16) -> 1816.237 | L22: =-('Balance Sheet'!L8-'Balance Sheet'!K8)-('Balance Sheet'!L16-'Balance Sheet'!K16) -> 1779.9123 | M22: =-('Balance Sheet'!M8-'Balance Sheet'!L8)-('Balance Sheet'!M16-'Balance Sheet'!L16) -> 1744.314 | N22: =-('Balance Sheet'!N8-'Balance Sheet'!M8)-('Balance Sheet'!N16-'Balance Sheet'!M16) -> 1709.4278 | O22: =-('Balance Sheet'!O8-'Balance Sheet'!N8)-('Balance Sheet'!O16-'Balance Sheet'!N16) -> 1675.2392
B23: Proceeds from maturities of marketable securities | D23: 29917 | E23: 39686 | F23: 51211 | G23: 40907
B24: Proceeds from sales of marketable securities | D24: 37446 | E24: 5828 | F24: 11135 | G24: 12890
B25: Payments for acquisition of property plant and equipment | D25: -10708 | E25: -10959 | F25: -9447 | G25: -12715 | H25: =-Schedules!H30 -> -13766.93 | I25: =-Schedules!I30 -> -14533.787 | J25: =-Schedules!J30 -> -15325.266 | K25: =-Schedules!K30 -> -16091.791 | L25: =-Schedules!L30 -> -16862.423 | M25: =-Schedules!M30 -> -17591.022 | N25: =-Schedules!N30 -> -18365.241 | O25: =-Schedules!O30 -> -19124.969
B26: Other | D26: -2086 | E26: -1337 | F26: -1308 | G26: -1480
B27: Cash generated by investing activities | D27: =SUM(D22:D26) -> -22354 | E27: =SUM(E22:E26) -> 3705 | F27: =SUM(F22:F26) -> 2935 | G27: =SUM(G22:G26) -> 15195 | H27: =SUM(H22:H26) -> -11837.21 | I27: =SUM(I22:I26) -> -12642.661 | J27: =SUM(J22:J26) -> -13471.963 | K27: =SUM(K22:K26) -> -14275.554 | ... O27: =SUM(O22:O26) -> -17449.73
B29: Financing activities:
B30: Payments for taxes related to net share settlement of equity awards | D30: -6223 | E30: -5431 | F30: -5441 | G30: -5960 | H30: =-'Income Statement'!H8*Assumptions!H49 -> -6350.5516 | I30: =-'Income Statement'!I8*Assumptions!I49 -> -6704.2951 | J30: =-'Income Statement'!J8*Assumptions!J49 -> -7069.3971 | K30: =-'Income Statement'!K8*Assumptions!K49 -> -7422.9875 | L30: =-'Income Statement'!L8*Assumptions!L49 -> -7778.4724 | M30: =-'Income Statement'!M8*Assumptions!M49 -> -8114.568 | N30: =-'Income Statement'!N8*Assumptions!N49 -> -8471.7077 | O30: =-'Income Statement'!O8*Assumptions!O49 -> -8822.1631 | P30: Source: Apple 10-K FY2025 p.33 CFS — RSU taxes $5,960M; projected at 1.43% of revenue
B31: Payments for dividends and dividend equivalents | D31: -14841 | E31: -15025 | F31: -15234 | G31: -15421 | H31: =-Assumptions!H44 -> -16029.52 | I31: =-Assumptions!I44 -> -16670.701 | J31: =-Assumptions!J44 -> -17337.529 | K31: =-Assumptions!K44 -> -18031.03 | L31: =-Assumptions!L44 -> -18752.271 | M31: =-Assumptions!M44 -> -19502.362 | N31: =-Assumptions!N44 -> -20282.457 | O31: =-Assumptions!O44 -> -21093.755
B32: Repurchases of common stock | D32: -89402 | E32: -77550 | F32: -94949 | G32: -90711 | H32: =-Assumptions!H46 -> -89300 | I32: =-Assumptions!I46 -> -85000 | J32: =-Assumptions!J46 -> -80000 | K32: =-Assumptions!K46 -> -75000 | L32: =-Assumptions!L46 -> -70000 | M32: =-Assumptions!M46 -> -65000 | N32: =-Assumptions!N46 -> -60000 | O32: =-Assumptions!O46 -> -55000
B33: Proceeds from issuance of term debt net | D33: 5465 | E33: 5228 | F33: 0 | G33: 4481 | H33: 0 | I33: 0 | J33: 0 | K33: 0 | L33: 0 | M33: 0 | N33: 0 | O33: 0
B34: Repayments of term debt | D34: -9543 | E34: -11151 | F34: -9958 | G34: -10932 | H34: -12393 | I34: -10078 | J34: -9300 | K34: -5235 | L34: -4972 | M34: -8254 | N34: -8254 | O34: -8254 | P34: Source: Apple 10-K FY2025, Note 9 p.43 — Future Principal Payments: FY26=$12,393M FY27=$10,078M FY28=$9,300M FY29=$5,235M FY30=$4,972M FY31-33=$49,303M÷3≈$8,254M per year
B35: Proceeds from/(Repayments of) commercial paper net | D35: 3955 | E35: -3978 | F35: 3960 | G35: -2032 | H35: 0 | I35: 0 | J35: 0 | K35: 0 | L35: 0 | M35: 0 | N35: 0 | O35: 0
B36: Other | D36: -160 | E36: -581 | F36: -361 | G36: -111 | H36: 0 | I36: 0 | J36: 0 | K36: 0 | L36: 0 | M36: 0 | N36: 0 | O36: 0
B37: Cash used in financing activities | D37: =SUM(D30:D36) -> -110749 | E37: =SUM(E30:E36) -> -108488 | F37: =SUM(F30:F36) -> -121983 | G37: =SUM(G30:G36) -> -120686 | H37: =SUM(H30:H36) -> -124073.07 | I37: =SUM(I30:I36) -> -118453 | J37: =SUM(J30:J36) -> -113706.93 | K37: =SUM(K30:K36) -> -105689.02 | ... O37: =SUM(O30:O36) -> -93169.918
B39: Increase/(Decrease) in cash cash equivalents and restricted cash and cash equivalents | D39: -10952 | E39: 5760 | F39: -794 | G39: 5991 | H39: =H19+H27+H37 -> 9239.3001 | I39: =I19+I27+I37 -> 23230.198 | J39: =J19+J27+J37 -> 37282.473 | K39: =K19+K27+K37 -> 54232.013 | L39: =L19+L27+L37 -> 68083.028 | M39: =M19+M27+M37 -> 78149.694 | N39: =N19+N27+N37 -> 92090.464 | O39: =O19+O27+O37 -> 105997.56
B40: Cash cash equivalents and restricted cash and cash equivalents ending balances | D40: =D4+D39 -> 24977 | E40: =E4+E39 -> 30737 | F40: =F4+F39 -> 29943 | G40: =G4+G39 -> 35934 | H40: =H4+H39 -> 45173.3 | I40: =I4+I39 -> 68403.499 | J40: =J4+J39 -> 105685.97 | K40: =K4+K39 -> 159917.98 | ... O40: =O4+O39 -> 504238.73
B42: Supplemental cash flow disclosure:
B43: Cash paid for income taxes net | D43: 19573 | E43: 18679 | F43: 26102 | G43: 43369 | H43: ='Income Statement'!H21*0.9 -> 20604.565 | I43: ='Income Statement'!I21*0.9 -> 22157.367 | J43: ='Income Statement'!J21*0.9 -> 23719.953 | K43: ='Income Statement'!K21*0.9 -> 25205.351 | L43: ='Income Statement'!L21*0.9 -> 26882.401 | M43: ='Income Statement'!M21*0.9 -> 28452.513 | N43: ='Income Statement'!N21*0.9 -> 30131.317 | O43: ='Income Statement'!O21*0.9 -> 31821.974 | P43: Memo item only, not included in operating CF total. Approx = P&L tax provision × 90%
B45: Notes:
B46: Source: Apple 10-K FY2025, Note 1 — Reconciliation of cash, cash equivalents and restricted cash. CFS includes restricted cash per ASC 230; Balance Sheet excludes it per ASC 210. Restricted cash relates to deposits securing lease obligations. FY2022 = $1,331M | FY2023 = $772M | FY2024+ = $0.

Sheet Schedules
B2: =Cover!F5&" Schedules" -> Apple Inc. Schedules
B3: Working Capital Schedule
D4: 2022 | E4: =D4+1 -> 2023 | F4: =E4+1 -> 2024 | G4: =F4+1 -> 2025 | H4: =G4+1 -> 2026 | I4: =H4+1 -> 2027 | J4: =I4+1 -> 2028 | K4: =J4+1 -> 2029 | L4: =K4+1 -> 2030 | ... O4: =N4+1 -> 2033
B5: Source: Apple 10-K FY2025 p.31 Balance Sheet | DSO/DIO/DPO from Assumptions tab
B6: Current Assets
B7: Accounts receivable | D7: ='Balance Sheet'!D9 -> 28184 | E7: ='Balance Sheet'!E9 -> 29508 | F7: ='Balance Sheet'!F9 -> 33410 | G7: ='Balance Sheet'!G9 -> 39777 | H7: ='Balance Sheet'!H9 -> 42584.406 | I7: ='Balance Sheet'!I9 -> 44956.476 | J7: ='Balance Sheet'!J9 -> 47404.713 | K7: ='Balance Sheet'!K9 -> 49775.757 | ... O7: ='Balance Sheet'!O9 -> 59158.101
B8: DSO (days) | D8: =Assumptions!D24 -> 27 | E8: =Assumptions!E24 -> 28 | F8: =Assumptions!F24 -> 31 | G8: =Assumptions!G24 -> 35 | H8: =Assumptions!H24 -> 35 | I8: =Assumptions!I24 -> 35 | J8: =Assumptions!J24 -> 35 | K8: =Assumptions!K24 -> 35 | ... O8: =Assumptions!O24 -> 35
B9: Inventories | D9: ='Balance Sheet'!D11 -> 4946 | E9: ='Balance Sheet'!E11 -> 6331 | F9: ='Balance Sheet'!F11 -> 7286 | G9: ='Balance Sheet'!G11 -> 5718 | H9: ='Balance Sheet'!H11 -> 5814.5965 | I9: ='Balance Sheet'!I11 -> 6069.1243 | J9: ='Balance Sheet'!J11 -> 6326.4975 | K9: ='Balance Sheet'!K11 -> 6578.9329 | ... O9: ='Balance Sheet'!O11 -> 7438.7087
B10: DIO (days) | D10: =Assumptions!D25 -> 9 | E10: =Assumptions!E25 -> 8 | F10: =Assumptions!F25 -> 13 | G10: =Assumptions!G25 -> 9 | H10: =Assumptions!H25 -> 9 | I10: =Assumptions!I25 -> 9 | J10: =Assumptions!J25 -> 9 | K10: =Assumptions!K25 -> 9 | ... O10: =Assumptions!O25 -> 9
B12: Current Liabilities
B13: Accounts payable | D13: ='Balance Sheet'!D24 -> 64115 | E13: ='Balance Sheet'!E24 -> 62611 | F13: ='Balance Sheet'!F24 -> 68960 | G13: ='Balance Sheet'!G24 -> 69860 | H13: ='Balance Sheet'!H24 -> 74297.622 | I13: ='Balance Sheet'!I24 -> 77549.922 | J13: ='Balance Sheet'!J24 -> 80838.579 | K13: ='Balance Sheet'!K24 -> 84064.142 | ... O13: ='Balance Sheet'!O24 -> 95050.166
B14: DPO (days) | D14: =Assumptions!D26 -> 107 | E14: =Assumptions!E26 -> 109 | F14: =Assumptions!F26 -> 120 | G14: =Assumptions!G26 -> 115 | H14: =Assumptions!H26 -> 115 | I14: =Assumptions!I26 -> 115 | J14: =Assumptions!J26 -> 115 | K14: =Assumptions!K26 -> 115 | ... O14: =Assumptions!O26 -> 115
B15: Net Working Capital | D15: =D7+D9+D13 -> 97245 | E15: =E7+E9+E13 -> 98450 | F15: =F7+F9-F13 -> -28264 | G15: =G7+G9-G13 -> -24365 | H15: =H7+H9-H13 -> -25898.619 | I15: =I7+I9-I13 -> -26524.321 | J15: =J7+J9-J13 -> -27107.369 | K15: =K7+K9-K13 -> -27709.453 | L15: =L7+L9-L13 -> -27930.669 | M15: =M7+M9-M13 -> -28148.744 | ... O15: =O7+O9-O13 -> -28453.356
B16: Change in net working capital | E16: =F15-E15 -> -126714 | F16: =G15-F15 -> 3899 | G16: =H15-G15 -> -1533.619 | H16: =I15-H15 -> -625.702 | I16: =J15-I15 -> -583.04803 | J16: =K15-J15 -> -602.08354 | K16: =L15-K15 -> -221.21683 | L16: =M15-L15 -> -218.07448 | ... N16: =O15-N15 -> -98.009365 | O16: =O15-N15 -> -98.009365
B19: Fixed Assets Schedule
B20: in $ millions | D20: 2022 | E20: =D20+1 -> 2023 | F20: =E20+1 -> 2024 | G20: =F20+1 -> 2025 | H20: =G20+1 -> 2026 | I20: =H20+1 -> 2027 | J20: =I20+1 -> 2028 | K20: =J20+1 -> 2029 | L20: =K20+1 -> 2030 | ... O20: =N20+1 -> 2033
B21: Source: Apple 10-K FY2025 Note 5, p.39 | Capex: CFS p.33 | D&A: CFS p.33
B22: Land and buildings | D22: 22126 | E22: 23446 | F22: 24690 | G22: 27337
B23: Machinery, equipment and internal-use software | D23: 81060 | E23: 78314 | F23: 80205 | G23: 83420
B24: Leasehold improvemens | D24: 11271 | E24: 12839 | F24: 14233 | G24: 15091
B25: Gross property, plant and equipment | D25: =SUM(D22:D24) -> 114457 | E25: =SUM(E22:E24) -> 114599 | F25: =SUM(F22:F24) -> 119128 | G25: =SUM(G22:G24) -> 125848
B26: Accumulated depreciation | D26: -72340 | E26: -70884 | F26: -73448 | G26: -76014
B27: Total property, plant and equipment, net | D27: =D25+D26 -> 42117 | E27: =E25+E26 -> 43715 | F27: =F25+F26 -> 45680 | G27: =G25+G26 -> 49834
B29: Beginning PP&E | D29: 39440 | E29: 42117 | F29: 43715 | G29: 45680 | H29: 49834 | I29: =H32 -> 54877.271 | J29: =I32 -> 60521.649 | K29: =J32 -> 66788.608 | L29: =K32 -> 73649.984 | M29: =L32 -> 81106.614 | N29: =M32 -> 89113.132 | O29: =N32 -> 97711.764
B30: Capital Expenditures | D30: 10708 | E30: 10959 | F30: 9447 | G30: 12715 | H30: ='Income Statement'!H8*Assumptions!H21 -> 13766.93 | I30: ='Income Statement'!I8*Assumptions!I21 -> 14533.787 | J30: ='Income Statement'!J8*Assumptions!J21 -> 15325.266 | K30: ='Income Statement'!K8*Assumptions!K21 -> 16091.791 | L30: ='Income Statement'!L8*Assumptions!L21 -> 16862.423 | M30: ='Income Statement'!M8*Assumptions!M21 -> 17591.022 | N30: ='Income Statement'!N8*Assumptions!N21 -> 18365.241 | O30: ='Income Statement'!O8*Assumptions!O21 -> 19124.969
B31: Depreciation related to PPE | D31: 8031 | E31: 9361 | F31: 7482 | G31: 8561 | H31: =G31*(1+Assumptions!H23) -> 8723.659 | I31: =Schedules!H31*(1+Assumptions!I23) -> 8889.4085 | J31: =Schedules!I31*(1+Assumptions!J23) -> 9058.3073 | K31: =Schedules!J31*(1+Assumptions!K23) -> 9230.4151 | L31: =Schedules!K31*(1+Assumptions!L23) -> 9405.793 | M31: =Schedules!L31*(1+Assumptions!M23) -> 9584.5031 | N31: =Schedules!M31*(1+Assumptions!N23) -> 9766.6086 | O31: =Schedules!N31*(1+Assumptions!O23) -> 9952.1742
B32: Ending PP&E | D32: =D29+D30-D31 -> 42117 | E32: =E29+E30-E31 -> 43715 | F32: =F29+F30-F31 -> 45680 | G32: =G29+G30-G31 -> 49834 | H32: =H29+H30-H31 -> 54877.271 | I32: =I29+I30-I31 -> 60521.649 | J32: =J29+J30-J31 -> 66788.608 | K32: =K29+K30-K31 -> 73649.984 | ... O32: =O29+O30-O31 -> 106884.56
B34: Fixed Assets Metrics:
B35: D&A related to PP&E as % of CapEx | D35: =D31/D30 -> 0.75 | E35: =E31/E30 -> 0.85418378 | F35: =F31/F30 -> 0.79199746 | G35: =G31/G30 -> 0.67329925 | H35: =H31/H30 -> 0.6336677 | I35: =I31/I30 -> 0.61163748 | J35: =J31/J30 -> 0.59107014 | K35: =K31/K30 -> 0.57361018 | ... O35: =O31/O30 -> 0.52037596
B37: Total Depreciation & Amortization | D37: ='Income Statement'!D24 -> 11104 | E37: ='Income Statement'!E24 -> 11519 | F37: ='Income Statement'!F24 -> 11445 | G37: ='Income Statement'!G24 -> 11698 | H37: ='Income Statement'!H24 -> 12434.647 | I37: ='Income Statement'!I24 -> 13127.291 | J37: ='Income Statement'!J24 -> 13842.176 | K37: ='Income Statement'!K24 -> 14534.521 | ... O37: ='Income Statement'!O24 -> 17274.166
B38: D&A not related to PPE | D38: =D37-D31 -> 3073 | E38: =E37-E31 -> 2158 | F38: =F37-F31 -> 3963 | G38: =G37-G31 -> 3137 | H38: =H37-H31 -> 3710.9876 | I38: =I37-I31 -> 4237.8826 | J38: =J37-J31 -> 4783.8688 | K38: =K37-K31 -> 5304.1058 | ... O38: =O37-O31 -> 7321.9914
B39: D&A not related to PPE as % of Revenue | D39: =D38/'Income Statement'!D8 -> 0.0077930048 | E39: =E38/'Income Statement'!E8 -> 0.0056302751 | F39: =F38/'Income Statement'!F8 -> 0.010134643 | G39: =G38/'Income Statement'!G8 -> 0.0075379481 | H39: =H38/'Income Statement'!H8 -> 0.0083563012 | I39: =I38/'Income Statement'!I8 -> 0.0090392383 | J39: =J38/'Income Statement'!J8 -> 0.0096768258 | K39: =K38/'Income Statement'!K8 -> 0.010218084 | ... O39: =O38/'Income Statement'!O8 -> 0.011868345
B40: Total D&A | D40: =D37 -> 11104 | E40: =E37 -> 11519 | F40: =F37 -> 11445 | G40: =G37 -> 11698 | H40: =H37 -> 12434.647 | I40: =I37 -> 13127.291 | J40: =J37 -> 13842.176 | K40: =K37 -> 14534.521 | ... O40: =O37 -> 17274.166
B43: Debt Schedule
D44: 2022 | E44: =D44+1 -> 2023 | F44: =E44+1 -> 2024 | G44: =F44+1 -> 2025 | H44: =G44+1 -> 2026 | I44: =H44+1 -> 2027 | J44: =I44+1 -> 2028 | K44: =J44+1 -> 2029 | L44: =K44+1 -> 2030 | ... O44: =N44+1 -> 2033
B45: Source: Apple 10-K FY2025 Note 9, p.43 | Future principal payments per maturity schedule
B46: Beginning term debt | D46: 111824 | E46: 110087 | F46: 105103 | G46: 96662 | H46: =G50 -> 90678 | I46: =H50 -> 78285 | J46: =I50 -> 68207 | K46: =J50 -> 58907 | L46: =K50 -> 53672 | M46: =L50 -> 48700 | N46: =M50 -> 40446 | O46: =N50 -> 32192
B47: New issuances | E47: 5228 | G47: 4481
